<?xml version="1.0" encoding="utf-8"?>
<!DOCTYPE TS>
<TS version="2.0" language="fr_FR">
<context>
    <name>HttpFinder</name>
    <message>
        <location filename="../http_finder.py" line="102"/>
        <source>The service did not reply properly. Please check service definition.</source>
        <translation>Le service n&apos;a pas répondu correctement. Vérifier que le service est disponible.</translation>
    </message>
    <message>
        <location filename="../http_finder.py" line="123"/>
        <source>The remote server refused the connection (the server is not accepting requests)</source>
        <translation>Le serveur distant refuse la connection (le serveur n&apos;accepte pas les requêtes)</translation>
    </message>
    <message>
        <location filename="../http_finder.py" line="127"/>
        <source>The remote server closed the connection prematurely, before the entire reply was received and processed</source>
        <translation>Le service distant a fermé la connexion prématurément, avant que la réponse soit complètement reçue et traitée</translation>
    </message>
    <message>
        <location filename="../http_finder.py" line="131"/>
        <source>The remote host name was not found (invalid hostname)</source>
        <translation>Le serveur distant n&apos;a pas été trouvé (nom de domaine incorrect)</translation>
    </message>
    <message>
        <location filename="../http_finder.py" line="134"/>
        <source>The connection to the remote server timed out</source>
        <translation>Le temps de connexion au serveur distant est dépassé</translation>
    </message>
    <message>
        <location filename="../http_finder.py" line="137"/>
        <source>The operation was canceled via calls to abort() or close() before it was finished.</source>
        <translation>L&apos;opération a été annulée avant d&apos;être terminée.</translation>
    </message>
    <message>
        <location filename="../http_finder.py" line="141"/>
        <source>The SSL/TLS handshake failed and the encrypted channel could not be established. The sslErrors() signal should have been emitted.</source>
        <translation>L&apos;établissement de liaison SSL / TLS a échoué et le canal chiffré n&apos;a pas pu être établi.</translation>
    </message>
    <message>
        <location filename="../http_finder.py" line="146"/>
        <source>The connection was broken due to disconnection from the network, however the system has initiated roaming to another access point. The request should be resubmitted and will be processed as soon as the connection is re-established.</source>
        <translation>La connexion a été perdue en raison d&apos;une déconnexion du réseau.Le système tente une reconnexion. La requête sera réenvoyée et traitée une fois le service rétabli.</translation>
    </message>
    <message>
        <location filename="../http_finder.py" line="154"/>
        <source>The connection to the proxy server was refused (the proxy server is not accepting requests)</source>
        <translation>La connection au proxy a été refusée (le proxy refuse les requêtes)</translation>
    </message>
    <message>
        <location filename="../http_finder.py" line="158"/>
        <source>The proxy server closed the connection prematurely, before the entire reply was received and processed</source>
        <translation>Le proxy a fermé la connexion prématurément, avant que la réponse soit complètement reçue et traitée</translation>
    </message>
    <message>
        <location filename="../http_finder.py" line="162"/>
        <source>The proxy host name was not found (invalid proxy hostname)</source>
        <translation>Le proxy n&apos;a pas été trouvé (nom de domaine pour le proxy incorrect)</translation>
    </message>
    <message>
        <location filename="../http_finder.py" line="165"/>
        <source>The connection to the proxy timed out or the proxy did not reply in time to the request sent</source>
        <translation>La connection au proxy a expirée ou le proxy n&apos;a pas répondu dans les temps à la requête</translation>
    </message>
    <message>
        <location filename="../http_finder.py" line="169"/>
        <source>The proxy requires authentication in order to honour the request but did not accept any credentials offered (if any)</source>
        <translation>Le proxy réclame une authentification pour lancer la requête</translation>
    </message>
    <message>
        <location filename="../http_finder.py" line="174"/>
        <source>The access to the remote content was denied (similar to HTTP error 401)</source>
        <translation>L&apos;accès au contenu distant a été refusé ( erreur HTTP 401)</translation>
    </message>
    <message>
        <location filename="../http_finder.py" line="177"/>
        <source>The operation requested on the remote content is not permitted</source>
        <translation>L&apos;opération demandée sur le contenu distant n&apos;est pas permise</translation>
    </message>
    <message>
        <location filename="../http_finder.py" line="180"/>
        <source>The remote content was not found at the server (similar to HTTP error 404)</source>
        <translation>Le contenu distant n&apos;a pas été trouvé sur le serveur (erreur HTTP 404)</translation>
    </message>
    <message>
        <location filename="../http_finder.py" line="183"/>
        <source>The remote server requires authentication to serve the content but the credentials provided were not accepted (if any)</source>
        <translation>Le serveur distant réclame une authentification pour lancer la requête</translation>
    </message>
    <message>
        <location filename="../http_finder.py" line="187"/>
        <source>The request needed to be sent again, but this failed for example because the upload data could not be read a second time.</source>
        <translation>La requête a nécéssité d&apos;être réenvoyée mais a échoué une nouvelle fois. La raison peut venir du fait que la donnée envoyé n&apos;a pu être lue.</translation>
    </message>
    <message>
        <location filename="../http_finder.py" line="191"/>
        <source>The Network Access API cannot honor the request because the protocol is not known</source>
        <translation>L&apos;API ne peut executé la requête car le protocole est inconnu</translation>
    </message>
    <message>
        <location filename="../http_finder.py" line="195"/>
        <source>the requested operation is invalid for this protocol</source>
        <translation>l&apos;opération demandé est invalide pour ce protocole</translation>
    </message>
    <message>
        <location filename="../http_finder.py" line="210"/>
        <source>An unknown network-related error was detected</source>
        <translation>Une erreur inconnue liée au réseau a été détectée</translation>
    </message>
    <message>
        <location filename="../http_finder.py" line="201"/>
        <source>An unknown proxy-related error was detected</source>
        <translation>Une erreur inconnue liée au proxy a été détectée</translation>
    </message>
    <message>
        <location filename="../http_finder.py" line="204"/>
        <source>An unknown error related to the remote content was detected</source>
        <translation>Une erreur inconue lié au serveur distant a été détectée</translation>
    </message>
    <message>
        <location filename="../http_finder.py" line="207"/>
        <source>A breakdown in protocol was detected (parsing error, invalid or unexpected responses, etc.)</source>
        <translation>Une panne lié au protocole a été dectée (parsing erreur,réponses invalides ou inatendues, etc)</translation>
    </message>
</context>
</TS>
